Workbook

Sheet main
B2: null hypothesis: | S2: bet on underdog | W2: bet on favorite | AA2: bet on draw | AE2: bet against favorite | AJ2: bet against underdog
B3: there is a positive edge in always betting on the underdog | M3: draw | S3: payoff | T3: =+SUM(U9:U1048576) -> 30.392028 | W3: payoff | X3: =+SUM(Y9:Y1048576) -> 60.093764 | AA3: payoff | AB3: =+SUM(AC9:AC1048576) -> 83.621018 | AE3: payoff | AF3: =+SUM(AG9:AG1048576) -> 71.155538 | AJ3: payoff | AK3: =+SUM(AL9:AL1048576) -> 40.496088
S4: cost | T4: =+COUNT(S10:S82) -> 62 | W4: cost | X4: =+COUNT(W10:W82) -> 62 | AA4: cost | AB4: =+COUNT(AA10:AA82) -> 62 | AE4: cost | AF4: =+COUNT(AE10:AE82) -> 62 | AJ4: cost | AK4: =+COUNT(AJ10:AJ82) -> 61
B5: avg bet | C5: 1 | S5: profit | T5: =+T3/T4-1 -> -0.50980599 | W5: profit | X5: =+X3/X4-1 -> -0.030745741 | AA5: profit | AB5: =+AB3/AB4-1 -> 0.34872609 | AE5: profit | AF5: =+AF3/AF4-1 -> 0.14766996 | AJ5: profit | AK5: =+AK3/AK4-1 -> -0.33612971
S6: winrate | T6: =+SUM(S10:S59)/COUNT(S10:S59) -> 0.08 | W6: winrate | X6: =+SUM(W10:W59)/COUNT(W10:W59) -> 0.64 | AA6: winrate | AB6: =+SUM(AA10:AA59)/COUNT(AA10:AA59) -> 0.28 | AE6: winrate | AF6: =+SUM(AE10:AE59)/COUNT(AE10:AE59) -> 0.36 | AJ6: winrate | AK6: =+SUM(AJ10:AJ59)/COUNT(AJ10:AJ59) -> 0.64
S8: underdog won | W8: favorite won | AA8: draw | AE8: bet against favorite | AJ8: bet against underdog
C9: T1 | D9: T2 | E9: T1 win | F9: Draw | G9: T2 Win | I9: bet | J9: on | K9: T1 goal | L9: T2goal | M9: result | N9: note | P9: underdog | Q9: favorite | S9: win/loss | T9: odds | U9: payoff | W9: win/loss | X9: odds | Y9: payoff | AA9: yes/no | AB9: odds | AC9: payoff | AE9: yes/no | AF9: odds | AG9: payoff | AJ9: yes/no | AK9: odds | AL9: payoff
B10: 46184 | C10: Mexico | D10: South Africa | E10: 0.685 | F10: 0.215 | G10: 0.105 | K10: 2 | L10: 0 | M10: =+IF(K10>L10,C10,IF(L10=K10,"draw",D10)) -> Mexico | N10: =IF(M10=P10,"dog win","fav win") -> fav win | P10: =+IF(G10<E10,D10,C10) -> South Africa | Q10: =+IF(P10=C10,D10,C10) -> Mexico | S10: =+IF(P10=M10,1,0) -> 0 | T10: =+IF(P10=C10,E10,G10) -> 0.105 | U10: =1/T10*S10 -> 0 | W10: =+IF(P10=M10,0,IF(M10="draw",0,1)) -> 1 | X10: =+IF(P10=C10,G10,E10) -> 0.685 | Y10: =1/X10*W10 -> 1.459854 | AA10: =+IF(M10="draw",1,0) -> 0 | AB10: =+F10 -> 0.215 | AC10: =1/AB10*AA10 -> 0 | AE10: =+IF(Q10=M10,0,1) -> 0 | AF10: =1-IF(C10=Q10,E10,G10) -> 0.315 | AG10: =1/AF10*AE10 -> 0 | AJ10: =+IF(Q10=M10,1,0) -> 1 | AK10: =1-IF(C10=P10,E10,G10) -> 0.895 | AL10: =1/AK10*AJ10 -> 1.1173184
B11: 46184 | C11: South Korea | D11: Czechia | E11: 0.375 | F11: 0.315 | G11: 0.315 | K11: 2 | L11: 1 | M11: =+IF(K11>L11,C11,IF(L11=K11,"draw",D11)) -> South Korea | N11: =IF(M11="draw","draw",IF(M11=P11,"dog win","fav win")) -> fav win | P11: =+IF(G11<E11,D11,C11) -> Czechia | Q11: =+IF(P11=C11,D11,C11) -> South Korea | S11: =+IF(P11=M11,1,0) -> 0 | T11: =+IF(P11=C11,E11,G11) -> 0.315 | U11: =1/T11*S11 -> 0 | W11: =+IF(P11=M11,0,IF(M11="draw",0,1)) -> 1 | X11: =+IF(P11=C11,G11,E11) -> 0.375 | Y11: =1/X11*W11 -> 2.6666667 | AA11: =+IF(M11="draw",1,0) -> 0 | AB11: =+F11 -> 0.315 | AC11: =1/AB11*AA11 -> 0 | AE11: =+IF(Q11=M11,0,1) -> 0 | AF11: =1-IF(C11=Q11,E11,G11) -> 0.625 | AG11: =1/AF11*AE11 -> 0 | AJ11: =+IF(Q11=M11,1,0) -> 1 | AK11: =1-IF(C11=P11,E11,G11) -> 0.685 | AL11: =1/AK11*AJ11 -> 1.459854
B12: 46185 | C12: Canada | D12: Bosnia-Herzegovina | E12: 0.54 | F12: 0.28 | G12: 0.2 | I12: 1 | J12: Bosnia-Herzegovina | K12: 1 | L12: 1 | M12: =+IF(K12>L12,C12,IF(L12=K12,"draw",D12)) -> draw | N12: =IF(M12="draw","draw",IF(M12=P12,"dog win","fav win")) -> draw | P12: =+IF(G12<E12,D12,C12) -> Bosnia-Herzegovina | Q12: =+IF(P12=C12,D12,C12) -> Canada | S12: =+IF(P12=M12,1,0) -> 0 | T12: =+IF(P12=C12,E12,G12) -> 0.2 | U12: =1/T12*S12 -> 0 | W12: =+IF(P12=M12,0,IF(M12="draw",0,1)) -> 0 | X12: =+IF(P12=C12,G12,E12) -> 0.54 | Y12: =1/X12*W12 -> 0 | AA12: =+IF(M12="draw",1,0) -> 1 | AB12: =+F12 -> 0.28 | AC12: =1/AB12*AA12 -> 3.5714286 | AE12: =+IF(Q12=M12,0,1) -> 1 | AF12: =1-IF(C12=Q12,E12,G12) -> 0.46 | AG12: =1/AF12*AE12 -> 2.173913 | AJ12: =+IF(Q12=M12,1,0) -> 0 | AK12: =1-IF(C12=P12,E12,G12) -> 0.8 | AL12: =1/AK12*AJ12 -> 0
B13: 46185 | C13: USA | D13: Paraguay | E13: 0.47 | F13: 0.3 | G13: 0.24 | I13: 1 | J13: Paraguay | K13: 4 | L13: 1 | M13: =+IF(K13>L13,C13,IF(L13=K13,"draw",D13)) -> USA | N13: =IF(M13="draw","draw",IF(M13=P13,"dog win","fav win")) -> fav win | P13: =+IF(G13<E13,D13,C13) -> Paraguay | Q13: =+IF(P13=C13,D13,C13) -> USA | S13: =+IF(P13=M13,1,0) -> 0 | T13: =+IF(P13=C13,E13,G13) -> 0.24 | U13: =1/T13*S13 -> 0 | W13: =+IF(P13=M13,0,IF(M13="draw",0,1)) -> 1 | X13: =+IF(P13=C13,G13,E13) -> 0.47 | Y13: =1/X13*W13 -> 2.1276596 | AA13: =+IF(M13="draw",1,0) -> 0 | AB13: =+F13 -> 0.3 | AC13: =1/AB13*AA13 -> 0 | AE13: =+IF(Q13=M13,0,1) -> 0 | AF13: =1-IF(C13=Q13,E13,G13) -> 0.53 | AG13: =1/AF13*AE13 -> 0 | AJ13: =+IF(Q13=M13,1,0) -> 1 | AK13: =1-IF(C13=P13,E13,G13) -> 0.76 | AL13: =1/AK13*AJ13 -> 1.3157895
B14: 46186 | C14: Qatar | D14: Switzerland | E14: 0.059 | F14: 0.14 | G14: 0.81 | I14: 1 | J14: Qatar | K14: 1 | L14: 1 | M14: =+IF(K14>L14,C14,IF(L14=K14,"draw",D14)) -> draw | N14: =IF(M14="draw","draw",IF(M14=P14,"dog win","fav win")) -> draw | P14: =+IF(G14<E14,D14,C14) -> Qatar | Q14: =+IF(P14=C14,D14,C14) -> Switzerland | S14: =+IF(P14=M14,1,0) -> 0 | T14: =+IF(P14=C14,E14,G14) -> 0.059 | U14: =1/T14*S14 -> 0 | W14: =+IF(P14=M14,0,IF(M14="draw",0,1)) -> 0 | X14: =+IF(P14=C14,G14,E14) -> 0.81 | Y14: =1/X14*W14 -> 0 | AA14: =+IF(M14="draw",1,0) -> 1 | AB14: =+F14 -> 0.14 | AC14: =1/AB14*AA14 -> 7.1428571 | AE14: =+IF(Q14=M14,0,1) -> 1 | AF14: =1-IF(C14=Q14,E14,G14) -> 0.19 | AG14: =1/AF14*AE14 -> 5.2631579 | AJ14: =+IF(Q14=M14,1,0) -> 0 | AK14: =1-IF(C14=P14,E14,G14) -> 0.941 | AL14: =1/AK14*AJ14 -> 0
B15: 46186 | C15: Brazil | D15: Morocco | E15: 0.6 | F15: 0.25 | G15: 0.17 | I15: 1 | J15: Morocco | K15: 1 | L15: 1 | M15: =+IF(K15>L15,C15,IF(L15=K15,"draw",D15)) -> draw | N15: =IF(M15="draw","draw",IF(M15=P15,"dog win","fav win")) -> draw | P15: =+IF(G15<E15,D15,C15) -> Morocco | Q15: =+IF(P15=C15,D15,C15) -> Brazil | S15: =+IF(P15=M15,1,0) -> 0 | T15: =+IF(P15=C15,E15,G15) -> 0.17 | U15: =1/T15*S15 -> 0 | W15: =+IF(P15=M15,0,IF(M15="draw",0,1)) -> 0 | X15: =+IF(P15=C15,G15,E15) -> 0.6 | Y15: =1/X15*W15 -> 0 | AA15: =+IF(M15="draw",1,0) -> 1 | AB15: =+F15 -> 0.25 | AC15: =1/AB15*AA15 -> 4 | AE15: =+IF(Q15=M15,0,1) -> 1 | AF15: =1-IF(C15=Q15,E15,G15) -> 0.4 | AG15: =1/AF15*AE15 -> 2.5 | AJ15: =+IF(Q15=M15,1,0) -> 0 | AK15: =1-IF(C15=P15,E15,G15) -> 0.83 | AL15: =1/AK15*AJ15 -> 0
B16: 46186 | C16: Haiti | D16: Scotland | E16: 0.16 | F16: 0.23 | G16: 0.62 | I16: 1 | J16: Haiti | K16: 0 | L16: 1 | M16: =+IF(K16>L16,C16,IF(L16=K16,"draw",D16)) -> Scotland | N16: =IF(M16="draw","draw",IF(M16=P16,"dog win","fav win")) -> fav win | P16: =+IF(G16<E16,D16,C16) -> Haiti | Q16: =+IF(P16=C16,D16,C16) -> Scotland | S16: =+IF(P16=M16,1,0) -> 0 | T16: =+IF(P16=C16,E16,G16) -> 0.16 | U16: =1/T16*S16 -> 0 | W16: =+IF(P16=M16,0,IF(M16="draw",0,1)) -> 1 | X16: =+IF(P16=C16,G16,E16) -> 0.62 | Y16: =1/X16*W16 -> 1.6129032 | AA16: =+IF(M16="draw",1,0) -> 0 | AB16: =+F16 -> 0.23 | AC16: =1/AB16*AA16 -> 0 | AE16: =+IF(Q16=M16,0,1) -> 0 | AF16: =1-IF(C16=Q16,E16,G16) -> 0.38 | AG16: =1/AF16*AE16 -> 0 | AJ16: =+IF(Q16=M16,1,0) -> 1 | AK16: =1-IF(C16=P16,E16,G16) -> 0.84 | AL16: =1/AK16*AJ16 -> 1.1904762
B17: 46187 | C17: Australia | D17: Turkey | E17: 0.19 | F17: 0.26 | G17: 0.57 | K17: 2 | L17: 0 | M17: =+IF(K17>L17,C17,IF(L17=K17,"draw",D17)) -> Australia | N17: =IF(M17="draw","draw",IF(M17=P17,"dog win","fav win")) -> dog win | P17: =+IF(G17<E17,D17,C17) -> Australia | Q17: =+IF(P17=C17,D17,C17) -> Turkey | S17: =+IF(P17=M17,1,0) -> 1 | T17: =+IF(P17=C17,E17,G17) -> 0.19 | U17: =1/T17*S17 -> 5.2631579 | W17: =+IF(P17=M17,0,IF(M17="draw",0,1)) -> 0 | X17: =+IF(P17=C17,G17,E17) -> 0.57 | Y17: =1/X17*W17 -> 0 | AA17: =+IF(M17="draw",1,0) -> 0 | AB17: =+F17 -> 0.26 | AC17: =1/AB17*AA17 -> 0 | AE17: =+IF(Q17=M17,0,1) -> 1 | AF17: =1-IF(C17=Q17,E17,G17) -> 0.43 | AG17: =1/AF17*AE17 -> 2.3255814 | AJ17: =+IF(Q17=M17,1,0) -> 0 | AK17: =1-IF(C17=P17,E17,G17) -> 0.81 | AL17: =1/AK17*AJ17 -> 0
B18: 46187 | C18: Germany | D18: Curcao | E18: 0.941 | F18: 0.04 | G18: 0.022 | K18: 7 | L18: 1 | M18: =+IF(K18>L18,C18,IF(L18=K18,"draw",D18)) -> Germany | N18: =IF(M18="draw","draw",IF(M18=P18,"dog win","fav win")) -> fav win | P18: =+IF(G18<E18,D18,C18) -> Curcao | Q18: =+IF(P18=C18,D18,C18) -> Germany | S18: =+IF(P18=M18,1,0) -> 0 | T18: =+IF(P18=C18,E18,G18) -> 0.022 | U18: =1/T18*S18 -> 0 | W18: =+IF(P18=M18,0,IF(M18="draw",0,1)) -> 1 | X18: =+IF(P18=C18,G18,E18) -> 0.941 | Y18: =1/X18*W18 -> 1.0626993 | AA18: =+IF(M18="draw",1,0) -> 0 | AB18: =+F18 -> 0.04 | AC18: =1/AB18*AA18 -> 0 | AE18: =+IF(Q18=M18,0,1) -> 0 | AF18: =1-IF(C18=Q18,E18,G18) -> 0.059 | AG18: =1/AF18*AE18 -> 0 | AJ18: =+IF(Q18=M18,1,0) -> 1 | AK18: =1-IF(C18=P18,E18,G18) -> 0.978 | AL18: =1/AK18*AJ18 -> 1.0224949
B19: 46187 | C19: Netherlands | D19: Japan | E19: 0.49 | F19: 0.27 | G19: 0.26 | K19: 2 | L19: 2 | M19: =+IF(K19>L19,C19,IF(L19=K19,"draw",D19)) -> draw | N19: =IF(M19="draw","draw",IF(M19=P19,"dog win","fav win")) -> draw | P19: =+IF(G19<E19,D19,C19) -> Japan | Q19: =+IF(P19=C19,D19,C19) -> Netherlands | S19: =+IF(P19=M19,1,0) -> 0 | T19: =+IF(P19=C19,E19,G19) -> 0.26 | U19: =1/T19*S19 -> 0 | W19: =+IF(P19=M19,0,IF(M19="draw",0,1)) -> 0 | X19: =+IF(P19=C19,G19,E19) -> 0.49 | Y19: =1/X19*W19 -> 0 | AA19: =+IF(M19="draw",1,0) -> 1 | AB19: =+F19 -> 0.27 | AC19: =1/AB19*AA19 -> 3.7037037 | AE19: =+IF(Q19=M19,0,1) -> 1 | AF19: =1-IF(C19=Q19,E19,G19) -> 0.51 | AG19: =1/AF19*AE19 -> 1.9607843 | AJ19: =+IF(Q19=M19,1,0) -> 0 | AK19: =1-IF(C19=P19,E19,G19) -> 0.74 | AL19: =1/AK19*AJ19 -> 0
B20: 46187 | C20: Ivory Cost | D20: Ecuador | E20: 0.27 | F20: 0.34 | G20: 0.4 | K20: 1 | L20: 0 | M20: =+IF(K20>L20,C20,IF(L20=K20,"draw",D20)) -> Ivory Cost | N20: =IF(M20="draw","draw",IF(M20=P20,"dog win","fav win")) -> dog win | P20: =+IF(G20<E20,D20,C20) -> Ivory Cost | Q20: =+IF(P20=C20,D20,C20) -> Ecuador | S20: =+IF(P20=M20,1,0) -> 1 | T20: =+IF(P20=C20,E20,G20) -> 0.27 | U20: =1/T20*S20 -> 3.7037037 | W20: =+IF(P20=M20,0,IF(M20="draw",0,1)) -> 0 | X20: =+IF(P20=C20,G20,E20) -> 0.4 | Y20: =1/X20*W20 -> 0 | AA20: =+IF(M20="draw",1,0) -> 0 | AB20: =+F20 -> 0.34 | AC20: =1/AB20*AA20 -> 0 | AE20: =+IF(Q20=M20,0,1) -> 1 | AF20: =1-IF(C20=Q20,E20,G20) -> 0.6 | AG20: =1/AF20*AE20 -> 1.6666667 | AJ20: =+IF(Q20=M20,1,0) -> 0 | AK20: =1-IF(C20=P20,E20,G20) -> 0.73 | AL20: =1/AK20*AJ20 -> 0
B21: 46187 | C21: Sweden | D21: Tunisia | E21: 0.52 | F21: 0.28 | G21: 0.22 | K21: 5 | L21: 1 | M21: =+IF(K21>L21,C21,IF(L21=K21,"draw",D21)) -> Sweden | N21: =IF(M21="draw","draw",IF(M21=P21,"dog win","fav win")) -> fav win | P21: =+IF(G21<E21,D21,C21) -> Tunisia | Q21: =+IF(P21=C21,D21,C21) -> Sweden | S21: =+IF(P21=M21,1,0) -> 0 | T21: =+IF(P21=C21,E21,G21) -> 0.22 | U21: =1/T21*S21 -> 0 | W21: =+IF(P21=M21,0,IF(M21="draw",0,1)) -> 1 | X21: =+IF(P21=C21,G21,E21) -> 0.52 | Y21: =1/X21*W21 -> 1.9230769 | AA21: =+IF(M21="draw",1,0) -> 0 | AB21: =+F21 -> 0.28 | AC21: =1/AB21*AA21 -> 0 | AE21: =+IF(Q21=M21,0,1) -> 0 | AF21: =1-IF(C21=Q21,E21,G21) -> 0.48 | AG21: =1/AF21*AE21 -> 0 | AJ21: =+IF(Q21=M21,1,0) -> 1 | AK21: =1-IF(C21=P21,E21,G21) -> 0.78 | AL21: =1/AK21*AJ21 -> 1.2820513
B22: 46188 | C22: Spain | D22: Cabo Verde | E22: 0.905 | F22: 0.069 | G22: 0.034 | K22: 0 | L22: 0 | M22: =+IF(K22>L22,C22,IF(L22=K22,"draw",D22)) -> draw | N22: =IF(M22="draw","draw",IF(M22=P22,"dog win","fav win")) -> draw | P22: =+IF(G22<E22,D22,C22) -> Cabo Verde | Q22: =+IF(P22=C22,D22,C22) -> Spain | S22: =+IF(P22=M22,1,0) -> 0 | T22: =+IF(P22=C22,E22,G22) -> 0.034 | U22: =1/T22*S22 -> 0 | W22: =+IF(P22=M22,0,IF(M22="draw",0,1)) -> 0 | X22: =+IF(P22=C22,G22,E22) -> 0.905 | Y22: =1/X22*W22 -> 0 | AA22: =+IF(M22="draw",1,0) -> 1 | AB22: =+F22 -> 0.069 | AC22: =1/AB22*AA22 -> 14.492754 | AE22: =+IF(Q22=M22,0,1) -> 1 | AF22: =1-IF(C22=Q22,E22,G22) -> 0.095 | AG22: =1/AF22*AE22 -> 10.526316 | AJ22: =+IF(Q22=M22,1,0) -> 0 | AK22: =1-IF(C22=P22,E22,G22) -> 0.966 | AL22: =1/AK22*AJ22 -> 0
B23: 46188 | C23: Belgium | D23: Egypt | E23: 0.655 | F23: 0.225 | G23: 0.125 | K23: 1 | L23: 1 | M23: =+IF(K23>L23,C23,IF(L23=K23,"draw",D23)) -> draw | N23: =IF(M23="draw","draw",IF(M23=P23,"dog win","fav win")) -> draw | P23: =+IF(G23<E23,D23,C23) -> Egypt | Q23: =+IF(P23=C23,D23,C23) -> Belgium | S23: =+IF(P23=M23,1,0) -> 0 | T23: =+IF(P23=C23,E23,G23) -> 0.125 | U23: =1/T23*S23 -> 0 | W23: =+IF(P23=M23,0,IF(M23="draw",0,1)) -> 0 | X23: =+IF(P23=C23,G23,E23) -> 0.655 | Y23: =1/X23*W23 -> 0 | AA23: =+IF(M23="draw",1,0) -> 1 | AB23: =+F23 -> 0.225 | AC23: =1/AB23*AA23 -> 4.4444444 | AE23: =+IF(Q23=M23,0,1) -> 1 | AF23: =1-IF(C23=Q23,E23,G23) -> 0.345 | AG23: =1/AF23*AE23 -> 2.8985507 | AJ23: =+IF(Q23=M23,1,0) -> 0 | AK23: =1-IF(C23=P23,E23,G23) -> 0.875 | AL23: =1/AK23*AJ23 -> 0
B24: 46188 | C24: Saudi Arabia | D24: Uruguay | E24: 0.125 | F24: 0.245 | G24: 0.635 | K24: 1 | L24: 1 | M24: =+IF(K24>L24,C24,IF(L24=K24,"draw",D24)) -> draw | N24: =IF(M24="draw","draw",IF(M24=P24,"dog win","fav win")) -> draw | P24: =+IF(G24<E24,D24,C24) -> Saudi Arabia | Q24: =+IF(P24=C24,D24,C24) -> Uruguay | S24: =+IF(P24=M24,1,0) -> 0 | T24: =+IF(P24=C24,E24,G24) -> 0.125 | U24: =1/T24*S24 -> 0 | W24: =+IF(P24=M24,0,IF(M24="draw",0,1)) -> 0 | X24: =+IF(P24=C24,G24,E24) -> 0.635 | Y24: =1/X24*W24 -> 0 | AA24: =+IF(M24="draw",1,0) -> 1 | AB24: =+F24 -> 0.245 | AC24: =1/AB24*AA24 -> 4.0816327 | AE24: =+IF(Q24=M24,0,1) -> 1 | AF24: =1-IF(C24=Q24,E24,G24) -> 0.365 | AG24: =1/AF24*AE24 -> 2.739726 | AJ24: =+IF(Q24=M24,1,0) -> 0 | AK24: =1-IF(C24=P24,E24,G24) -> 0.875 | AL24: =1/AK24*AJ24 -> 0
B25: 46188 | C25: Iran | D25: New Zeland | E25: 0.525 | F25: 0.285 | G25: 0.21 | K25: 2 | L25: 2 | M25: =+IF(K25>L25,C25,IF(L25=K25,"draw",D25)) -> draw | N25: =IF(M25="draw","draw",IF(M25=P25,"dog win","fav win")) -> draw | P25: =+IF(G25<E25,D25,C25) -> New Zeland | Q25: =+IF(P25=C25,D25,C25) -> Iran | S25: =+IF(P25=M25,1,0) -> 0 | T25: =+IF(P25=C25,E25,G25) -> 0.21 | U25: =1/T25*S25 -> 0 | W25: =+IF(P25=M25,0,IF(M25="draw",0,1)) -> 0 | X25: =+IF(P25=C25,G25,E25) -> 0.525 | Y25: =1/X25*W25 -> 0 | AA25: =+IF(M25="draw",1,0) -> 1 | AB25: =+F25 -> 0.285 | AC25: =1/AB25*AA25 -> 3.5087719 | AE25: =+IF(Q25=M25,0,1) -> 1 | AF25: =1-IF(C25=Q25,E25,G25) -> 0.475 | AG25: =1/AF25*AE25 -> 2.1052632 | AJ25: =+IF(Q25=M25,1,0) -> 0 | AK25: =1-IF(C25=P25,E25,G25) -> 0.79 | AL25: =1/AK25*AJ25 -> 0
B26: 46189 | C26: France | D26: Senegal | E26: 0.655 | F26: 0.215 | G26: 0.135 | K26: 3 | L26: 1 | M26: =+IF(K26>L26,C26,IF(L26=K26,"draw",D26)) -> France | N26: =IF(M26="draw","draw",IF(M26=P26,"dog win","fav win")) -> fav win | P26: =+IF(G26<E26,D26,C26) -> Senegal | Q26: =+IF(P26=C26,D26,C26) -> France | S26: =+IF(P26=M26,1,0) -> 0 | T26: =+IF(P26=C26,E26,G26) -> 0.135 | U26: =1/T26*S26 -> 0 | W26: =+IF(P26=M26,0,IF(M26="draw",0,1)) -> 1 | X26: =+IF(P26=C26,G26,E26) -> 0.655 | Y26: =1/X26*W26 -> 1.5267176 | AA26: =+IF(M26="draw",1,0) -> 0 | AB26: =+F26 -> 0.215 | AC26: =1/AB26*AA26 -> 0 | AE26: =+IF(Q26=M26,0,1) -> 0 | AF26: =1-IF(C26=Q26,E26,G26) -> 0.345 | AG26: =1/AF26*AE26 -> 0 | AJ26: =+IF(Q26=M26,1,0) -> 1 | AK26: =1-IF(C26=P26,E26,G26) -> 0.865 | AL26: =1/AK26*AJ26 -> 1.1560694
B27: 46189 | C27: Iraq | D27: Norway | E27: 0.019 | F27: 0.065 | G27: 0.915 | K27: 1 | L27: 4 | M27: =+IF(K27>L27,C27,IF(L27=K27,"draw",D27)) -> Norway | N27: =IF(M27="draw","draw",IF(M27=P27,"dog win","fav win")) -> fav win | P27: =+IF(G27<E27,D27,C27) -> Iraq | Q27: =+IF(P27=C27,D27,C27) -> Norway | S27: =+IF(P27=M27,1,0) -> 0 | T27: =+IF(P27=C27,E27,G27) -> 0.019 | U27: =1/T27*S27 -> 0 | W27: =+IF(P27=M27,0,IF(M27="draw",0,1)) -> 1 | X27: =+IF(P27=C27,G27,E27) -> 0.915 | Y27: =1/X27*W27 -> 1.0928962 | AA27: =+IF(M27="draw",1,0) -> 0 | AB27: =+F27 -> 0.065 | AC27: =1/AB27*AA27 -> 0 | AE27: =+IF(Q27=M27,0,1) -> 0 | AF27: =1-IF(C27=Q27,E27,G27) -> 0.085 | AG27: =1/AF27*AE27 -> 0 | AJ27: =+IF(Q27=M27,1,0) -> 1 | AK27: =1-IF(C27=P27,E27,G27) -> 0.981 | AL27: =1/AK27*AJ27 -> 1.019368
B28: 46189 | C28: Argentina | D28: Algeria | E28: 0.635 | F28: 0.235 | G28: 0.125 | K28: 3 | L28: 0 | M28: =+IF(K28>L28,C28,IF(L28=K28,"draw",D28)) -> Argentina | N28: =IF(M28="draw","draw",IF(M28=P28,"dog win","fav win")) -> fav win | P28: =+IF(G28<E28,D28,C28) -> Algeria | Q28: =+IF(P28=C28,D28,C28) -> Argentina | S28: =+IF(P28=M28,1,0) -> 0 | T28: =+IF(P28=C28,E28,G28) -> 0.125 | U28: =1/T28*S28 -> 0 | W28: =+IF(P28=M28,0,IF(M28="draw",0,1)) -> 1 | X28: =+IF(P28=C28,G28,E28) -> 0.635 | Y28: =1/X28*W28 -> 1.5748031 | AA28: =+IF(M28="draw",1,0) -> 0 | AB28: =+F28 -> 0.235 | AC28: =1/AB28*AA28 -> 0 | AE28: =+IF(Q28=M28,0,1) -> 0 | AF28: =1-IF(C28=Q28,E28,G28) -> 0.365 | AG28: =1/AF28*AE28 -> 0 | AJ28: =+IF(Q28=M28,1,0) -> 1 | AK28: =1-IF(C28=P28,E28,G28) -> 0.875 | AL28: =1/AK28*AJ28 -> 1.1428571
... B59: 46197 | C59: Qatar | D59: Bosnia-Herzegovina | E59: 0.01 | F59: 0.008 | G59: 0.994 | K59: 1 | L59: 3 | M59: =+IF(K59>L59,C59,IF(L59=K59,"draw",D59)) -> Bosnia-Herzegovina | N59: =IF(M59="draw","draw",IF(M59=P59,"dog win","fav win")) -> fav win | P59: =+IF(G59<E59,D59,C59) -> Qatar | Q59: =+IF(P59=C59,D59,C59) -> Bosnia-Herzegovina | S59: =+IF(P59=M59,1,0) -> 0 | T59: =+IF(P59=C59,E59,G59) -> 0.01 | U59: =1/T59*S59 -> 0 | W59: =+IF(P59=M59,0,IF(M59="draw",0,1)) -> 1 | X59: =+IF(P59=C59,G59,E59) -> 0.994 | Y59: =1/X59*W59 -> 1.0060362 | AA59: =+IF(M59="draw",1,0) -> 0 | AB59: =+F59 -> 0.008 | AC59: =1/AB59*AA59 -> 0 | AE59: =+IF(Q59=M59,0,1) -> 0 | AF59: =1-IF(C59=Q59,E59,G59) -> 0.006 | AG59: =1/AF59*AE59 -> 0 | AJ59: =+IF(Q59=M59,1,0) -> 1 | AK59: =1-IF(C59=P59,E59,G59) -> 0.99 | AL59: =1/AK59*AJ59 -> 1.010101
B60: 46197 | C60: Brazil | D60: Scotland | E60: 0.75 | F60: 0.17 | G60: 0.09 | I60: 1 | J60: Brazil | K60: 3 | L60: 0 | M60: =+IF(K60>L60,C60,IF(L60=K60,"draw",D60)) -> Brazil | N60: =IF(M60="draw","draw",IF(M60=P60,"dog win","fav win")) -> fav win | P60: =+IF(G60<E60,D60,C60) -> Scotland | Q60: =+IF(P60=C60,D60,C60) -> Brazil | S60: =+IF(P60=M60,1,0) -> 0 | T60: =+IF(P60=C60,E60,G60) -> 0.09 | U60: =1/T60*S60 -> 0 | W60: =+IF(P60=M60,0,IF(M60="draw",0,1)) -> 1 | X60: =+IF(P60=C60,G60,E60) -> 0.75 | Y60: =1/X60*W60 -> 1.3333333 | AA60: =+IF(M60="draw",1,0) -> 0 | AB60: =+F60 -> 0.17 | AC60: =1/AB60*AA60 -> 0 | AE60: =+IF(Q60=M60,0,1) -> 0 | AF60: =1-IF(C60=Q60,E60,G60) -> 0.25 | AG60: =1/AF60*AE60 -> 0 | AJ60: =+IF(Q60=M60,1,0) -> 1 | AK60: =1-IF(C60=P60,E60,G60) -> 0.91 | AL60: =1/AK60*AJ60 -> 1.0989011
B61: 46197 | C61: Haiti | D61: Morocco | E61: 0.06 | F61: 0.13 | G61: 0.83 | I61: 1 | J61: Morocco | K61: 2 | L61: 4 | M61: =+IF(K61>L61,C61,IF(L61=K61,"draw",D61)) -> Morocco | N61: =IF(M61="draw","draw",IF(M61=P61,"dog win","fav win")) -> fav win | P61: =+IF(G61<E61,D61,C61) -> Haiti | Q61: =+IF(P61=C61,D61,C61) -> Morocco | S61: =+IF(P61=M61,1,0) -> 0 | T61: =+IF(P61=C61,E61,G61) -> 0.06 | U61: =1/T61*S61 -> 0 | W61: =+IF(P61=M61,0,IF(M61="draw",0,1)) -> 1 | X61: =+IF(P61=C61,G61,E61) -> 0.83 | Y61: =1/X61*W61 -> 1.2048193 | AA61: =+IF(M61="draw",1,0) -> 0 | AB61: =+F61 -> 0.13 | AC61: =1/AB61*AA61 -> 0 | AE61: =+IF(Q61=M61,0,1) -> 0 | AF61: =1-IF(C61=Q61,E61,G61) -> 0.17 | AG61: =1/AF61*AE61 -> 0 | AJ61: =+IF(Q61=M61,1,0) -> 1 | AK61: =1-IF(C61=P61,E61,G61) -> 0.94 | AL61: =1/AK61*AJ61 -> 1.0638298
B62: 46197 | C62: Czechia | D62: Mexico | E62: 0.26 | F62: 0.25 | G62: 0.51 | K62: 0 | L62: 3 | M62: =+IF(K62>L62,C62,IF(L62=K62,"draw",D62)) -> Mexico | N62: =IF(M62="draw","draw",IF(M62=P62,"dog win","fav win")) -> fav win | P62: =+IF(G62<E62,D62,C62) -> Czechia | Q62: =+IF(P62=C62,D62,C62) -> Mexico | S62: =+IF(P62=M62,1,0) -> 0 | T62: =+IF(P62=C62,E62,G62) -> 0.26 | U62: =1/T62*S62 -> 0 | W62: =+IF(P62=M62,0,IF(M62="draw",0,1)) -> 1 | X62: =+IF(P62=C62,G62,E62) -> 0.51 | Y62: =1/X62*W62 -> 1.9607843 | AA62: =+IF(M62="draw",1,0) -> 0 | AB62: =+F62 -> 0.25 | AC62: =1/AB62*AA62 -> 0 | AE62: =+IF(Q62=M62,0,1) -> 0 | AF62: =1-IF(C62=Q62,E62,G62) -> 0.49 | AG62: =1/AF62*AE62 -> 0 | AJ62: =+IF(Q62=M62,1,0) -> 1 | AK62: =1-IF(C62=P62,E62,G62) -> 0.74 | AL62: =1/AK62*AJ62 -> 1.3513514
B63: 46197 | C63: South Africa | D63: South Korea | E63: 0.16 | F63: 0.24 | G63: 0.62 | K63: 1 | L63: 0 | M63: =+IF(K63>L63,C63,IF(L63=K63,"draw",D63)) -> South Africa | N63: =IF(M63="draw","draw",IF(M63=P63,"dog win","fav win")) -> dog win | P63: =+IF(G63<E63,D63,C63) -> South Africa | Q63: =+IF(P63=C63,D63,C63) -> South Korea | S63: =+IF(P63=M63,1,0) -> 1 | T63: =+IF(P63=C63,E63,G63) -> 0.16 | U63: =1/T63*S63 -> 6.25 | W63: =+IF(P63=M63,0,IF(M63="draw",0,1)) -> 0 | X63: =+IF(P63=C63,G63,E63) -> 0.62 | Y63: =1/X63*W63 -> 0 | AA63: =+IF(M63="draw",1,0) -> 0 | AB63: =+F63 -> 0.24 | AC63: =1/AB63*AA63 -> 0 | AE63: =+IF(Q63=M63,0,1) -> 1 | AF63: =1-IF(C63=Q63,E63,G63) -> 0.38 | AG63: =1/AF63*AE63 -> 2.6315789 | AJ63: =+IF(Q63=M63,1,0) -> 0 | AK63: =1-IF(C63=P63,E63,G63) -> 0.84 | AL63: =1/AK63*AJ63 -> 0
B64: 46198 | C64: Ecuador | D64: Germany | E64: 0.25 | F64: 0.23 | G64: 0.54 | I64: 1 | J64: Germany | K64: 2 | L64: 1 | M64: =+IF(K64>L64,C64,IF(L64=K64,"draw",D64)) -> Ecuador | N64: =IF(M64="draw","draw",IF(M64=P64,"dog win","fav win")) -> dog win | P64: =+IF(G64<E64,D64,C64) -> Ecuador | Q64: =+IF(P64=C64,D64,C64) -> Germany | S64: =+IF(P64=M64,1,0) -> 1 | T64: =+IF(P64=C64,E64,G64) -> 0.25 | U64: =1/T64*S64 -> 4 | W64: =+IF(P64=M64,0,IF(M64="draw",0,1)) -> 0 | X64: =+IF(P64=C64,G64,E64) -> 0.54 | Y64: =1/X64*W64 -> 0 | AA64: =+IF(M64="draw",1,0) -> 0 | AB64: =+F64 -> 0.23 | AC64: =1/AB64*AA64 -> 0 | AE64: =+IF(Q64=M64,0,1) -> 1 | AF64: =1-IF(C64=Q64,E64,G64) -> 0.46 | AG64: =1/AF64*AE64 -> 2.173913 | AJ64: =+IF(Q64=M64,1,0) -> 0
B65: 46198 | C65: Curacao | D65: Ivory Coast | E65: 0.06 | F65: 0.12 | G65: 0.84 | I65: 1 | J65: Ivory Coast | K65: 0 | L65: 2 | M65: =+IF(K65>L65,C65,IF(L65=K65,"draw",D65)) -> Ivory Coast | N65: =IF(M65="draw","draw",IF(M65=P65,"dog win","fav win")) -> fav win | P65: =+IF(G65<E65,D65,C65) -> Curacao | Q65: =+IF(P65=C65,D65,C65) -> Ivory Coast | S65: =+IF(P65=M65,1,0) -> 0 | T65: =+IF(P65=C65,E65,G65) -> 0.06 | U65: =1/T65*S65 -> 0 | W65: =+IF(P65=M65,0,IF(M65="draw",0,1)) -> 1 | X65: =+IF(P65=C65,G65,E65) -> 0.84 | Y65: =1/X65*W65 -> 1.1904762 | AA65: =+IF(M65="draw",1,0) -> 0 | AB65: =+F65 -> 0.12 | AC65: =1/AB65*AA65 -> 0 | AE65: =+IF(Q65=M65,0,1) -> 0 | AF65: =1-IF(C65=Q65,E65,G65) -> 0.16 | AG65: =1/AF65*AE65 -> 0 | AJ65: =+IF(Q65=M65,1,0) -> 1
B66: 46198 | C66: Japan | D66: Sweden | E66: 0.53 | F66: 0.27 | G66: 0.22 | K66: 1 | L66: 1 | M66: =+IF(K66>L66,C66,IF(L66=K66,"draw",D66)) -> draw | N66: =IF(M66="draw","draw",IF(M66=P66,"dog win","fav win")) -> draw | P66: =+IF(G66<E66,D66,C66) -> Sweden | Q66: =+IF(P66=C66,D66,C66) -> Japan | S66: =+IF(P66=M66,1,0) -> 0 | T66: =+IF(P66=C66,E66,G66) -> 0.22 | U66: =1/T66*S66 -> 0 | W66: =+IF(P66=M66,0,IF(M66="draw",0,1)) -> 0 | X66: =+IF(P66=C66,G66,E66) -> 0.53 | Y66: =1/X66*W66 -> 0 | AA66: =+IF(M66="draw",1,0) -> 1 | AB66: =+F66 -> 0.27 | AC66: =1/AB66*AA66 -> 3.7037037 | AE66: =+IF(Q66=M66,0,1) -> 1 | AF66: =1-IF(C66=Q66,E66,G66) -> 0.47 | AG66: =1/AF66*AE66 -> 2.1276596 | AJ66: =+IF(Q66=M66,1,0) -> 0
B67: 46198 | C67: Tunisia | D67: Netherlands | E67: 0.036 | F67: 0.1 | G67: 0.88 | I67: 1 | J67: Netherlands | K67: 1 | L67: 3 | M67: =+IF(K67>L67,C67,IF(L67=K67,"draw",D67)) -> Netherlands | N67: =IF(M67="draw","draw",IF(M67=P67,"dog win","fav win")) -> fav win | P67: =+IF(G67<E67,D67,C67) -> Tunisia | Q67: =+IF(P67=C67,D67,C67) -> Netherlands | S67: =+IF(P67=M67,1,0) -> 0 | T67: =+IF(P67=C67,E67,G67) -> 0.036 | U67: =1/T67*S67 -> 0 | W67: =+IF(P67=M67,0,IF(M67="draw",0,1)) -> 1 | X67: =+IF(P67=C67,G67,E67) -> 0.88 | Y67: =1/X67*W67 -> 1.1363636 | AA67: =+IF(M67="draw",1,0) -> 0 | AB67: =+F67 -> 0.1 | AC67: =1/AB67*AA67 -> 0 | AE67: =+IF(Q67=M67,0,1) -> 0 | AF67: =1-IF(C67=Q67,E67,G67) -> 0.12 | AG67: =1/AF67*AE67 -> 0 | AJ67: =+IF(Q67=M67,1,0) -> 1
B68: 46198 | C68: Turkey | D68: USA | E68: 0.27 | F68: 0.23 | G68: 0.52 | K68: 3 | L68: 2 | M68: =+IF(K68>L68,C68,IF(L68=K68,"draw",D68)) -> Turkey | N68: =IF(M68="draw","draw",IF(M68=P68,"dog win","fav win")) -> dog win | P68: =+IF(G68<E68,D68,C68) -> Turkey | Q68: =+IF(P68=C68,D68,C68) -> USA | S68: =+IF(P68=M68,1,0) -> 1 | T68: =+IF(P68=C68,E68,G68) -> 0.27 | U68: =1/T68*S68 -> 3.7037037 | W68: =+IF(P68=M68,0,IF(M68="draw",0,1)) -> 0 | X68: =+IF(P68=C68,G68,E68) -> 0.52 | Y68: =1/X68*W68 -> 0 | AA68: =+IF(M68="draw",1,0) -> 0 | AB68: =+F68 -> 0.23 | AC68: =1/AB68*AA68 -> 0 | AE68: =+IF(Q68=M68,0,1) -> 1 | AF68: =1-IF(C68=Q68,E68,G68) -> 0.48 | AG68: =1/AF68*AE68 -> 2.0833333 | AJ68: =+IF(Q68=M68,1,0) -> 0
B69: 46198 | C69: Paraguay | D69: Australia | E69: 0.34 | F69: 0.43 | G69: 0.24 | K69: 0 | L69: 0 | M69: =+IF(K69>L69,C69,IF(L69=K69,"draw",D69)) -> draw | N69: =IF(M69="draw","draw",IF(M69=P69,"dog win","fav win")) -> draw | P69: =+IF(G69<E69,D69,C69) -> Australia | Q69: =+IF(P69=C69,D69,C69) -> Paraguay | S69: =+IF(P69=M69,1,0) -> 0 | T69: =+IF(P69=C69,E69,G69) -> 0.24 | U69: =1/T69*S69 -> 0 | W69: =+IF(P69=M69,0,IF(M69="draw",0,1)) -> 0 | X69: =+IF(P69=C69,G69,E69) -> 0.34 | Y69: =1/X69*W69 -> 0 | AA69: =+IF(M69="draw",1,0) -> 1 | AB69: =+F69 -> 0.43 | AC69: =1/AB69*AA69 -> 2.3255814 | AE69: =+IF(Q69=M69,0,1) -> 1 | AF69: =1-IF(C69=Q69,E69,G69) -> 0.66 | AG69: =1/AF69*AE69 -> 1.5151515 | AJ69: =+IF(Q69=M69,1,0) -> 0
B70: 46199 | C70: Norway | D70: France | E70: 0.21 | F70: 0.21 | G70: 0.6 | I70: 1 | J70: France | K70: 1 | L70: 4 | M70: =+IF(K70>L70,C70,IF(L70=K70,"draw",D70)) -> France | N70: =IF(M70="draw","draw",IF(M70=P70,"dog win","fav win")) -> fav win | P70: =+IF(G70<E70,D70,C70) -> Norway | Q70: =+IF(P70=C70,D70,C70) -> France | S70: =+IF(P70=M70,1,0) -> 0 | T70: =+IF(P70=C70,E70,G70) -> 0.21 | U70: =1/T70*S70 -> 0 | W70: =+IF(P70=M70,0,IF(M70="draw",0,1)) -> 1 | X70: =+IF(P70=C70,G70,E70) -> 0.6 | Y70: =1/X70*W70 -> 1.6666667 | AA70: =+IF(M70="draw",1,0) -> 0 | AB70: =+F70 -> 0.21 | AC70: =1/AB70*AA70 -> 0 | AE70: =+IF(Q70=M70,0,1) -> 0 | AF70: =1-IF(C70=Q70,E70,G70) -> 0.4 | AG70: =1/AF70*AE70 -> 0 | AJ70: =+IF(Q70=M70,1,0) -> 1
B71: 46199 | C71: Senegal | D71: Iraq | E71: 0.8 | F71: 0.15 | G71: 0.07 | I71: 1 | J71: Senegal | K71: 5 | L71: 0 | M71: =+IF(K71>L71,C71,IF(L71=K71,"draw",D71)) -> Senegal | N71: =IF(M71="draw","draw",IF(M71=P71,"dog win","fav win")) -> fav win | P71: =+IF(G71<E71,D71,C71) -> Iraq | Q71: =+IF(P71=C71,D71,C71) -> Senegal | S71: =+IF(P71=M71,1,0) -> 0 | T71: =+IF(P71=C71,E71,G71) -> 0.07 | U71: =1/T71*S71 -> 0 | W71: =+IF(P71=M71,0,IF(M71="draw",0,1)) -> 1 | X71: =+IF(P71=C71,G71,E71) -> 0.8 | Y71: =1/X71*W71 -> 1.25 | AA71: =+IF(M71="draw",1,0) -> 0 | AB71: =+F71 -> 0.15 | AC71: =1/AB71*AA71 -> 0 | AE71: =+IF(Q71=M71,0,1) -> 0 | AF71: =1-IF(C71=Q71,E71,G71) -> 0.2 | AG71: =1/AF71*AE71 -> 0
B72: x | C72: x | D72: x | E72: x | F72: x | G72: x | H72: x | I72: x | J72: x | K72: x | L72: x | M72: x | N72: x | O72: x | P72: x | Q72: x | S72: x | T72: x | U72: x | V72: x | W72: x | X72: x | Y72: x | Z72: x | AA72: x | AB72: x | AC72: x | AD72: x | AE72: x | AF72: x | AG72: x | AH72: x | AI72: x | AJ72: x | AK72: x | AL72: x | AM72: x
...

Sheet comments
B2: 1 | C2: bet on underdog
C3: payoff | D3: =+main!T3 -> 30.392028 | I3: null hypothesis failed
C4: cost | D4: =+main!T4 -> 62 | I4: betting on the underdog loses money by 58%
C5: profit | D5: =+main!T5 -> -0.50980599
C6: winrate | D6: =+main!T6 -> 0.08
B8: 2 | C8: bet on favorite
C9: payoff | D9: =+main!X3 -> 60.093764 | I9: no edge in betting on the favorite
C10: cost | D10: =+main!X4 -> 62 | I10: initial suspected edge was a mistake
C11: profit | D11: =+main!X5 -> -0.030745741
C12: winrate | D12: =+main!X6 -> 0.64
B14: 3 | C14: bet on draw
C15: payoff | D15: =+main!AB3 -> 83.621018 | I15: surprise, it seems the market underestimates the possibility
C16: cost | D16: =+main!AB4 -> 62 | I16: of a draw
C17: profit | D17: =+main!AB5 -> 0.34872609
C18: winrate | D18: =+main!AB6 -> 0.28
B20: 4 | C20: bet against favorite
C21: payoff | D21: =+main!AF3 -> 71.155538 | I21: noticable edge in betting against the favorite, but since betting on the underdog has negative alpha
C22: cost | D22: =+main!AF4 -> 62 | I22: then the edge comes from the possibility of a draw
C23: profit | D23: =+main!AF5 -> 0.14766996
C24: winrate | D24: =+main!AF6 -> 0.36
B26: 5 | C26: bet against underdog
C27: payoff | D27: =+main!AK3 -> 40.496088 | I27: negative alpha due to the possibility of a draw
C28: cost | D28: =+main!AK4 -> 61
C29: profit | D29: =+main!AK5 -> -0.33612971
C30: winrate | D30: =+main!AK6 -> 0.64

Sheet sources
C5: polymarket
C6: fifa.com
